Workbook

Sheet ΦΥΛΛΟ ΑΠΟΛΟΓΙΣΜΟΥ
A1: ΦΥΛΛΟ ΑΠΟΛΟΓΙΣΜΟΥ ΕΡΓΑΣΙΩΝ FTTH Β ΦΑΣΗΣ
A2: ΕΡΓΟΛΑΒΙΑ: | C2: ΑΝΑΠΤΥΞΗ ΥΠΟΔΟΜΩΝ ΠΡΟΣΒΑΣΗΣ ΔΙΚΤΥΟΥ ΟΠΤΙΚΩΝ ΙΝΩΝ (FTTH Β ΦΑΣΗ) & ΔΙΑΣΥΝΔΕΣΗΣ ΤΟΝ ΤΕΛΙΚΟ ΧΡΗΣΤΗ (FTTH Γ ΦΑΣΗ) ΣΕ ΠΕΡΙΟΧΕΣ ΤΗΣ ΕΛΛΗΝΙΚΗΣ ΕΠΙΚΡΑΤΕΙΑΣ | E2: ΕΡΓΟΛΑΒΟΣ: | F2: ΕΡΓΑΤΗΚΑΤ
A3: ΥΠΟΕΡΓΟ: | E3: ΑΙΤΗΜΑ: | F3: 979273
A4: ΔΙΕΥΘΥΝΣΗ: | C4: ΛΕΩΦΟΡΟΣ ΓΕΩΡΓΙΟΥ ΑΒΕΡΩΦ 101Α
B5: Activity Number | C5: ΑΡΘΡΟ | D5: ΠΕΡΙΓΡΑΦΗ ΑΡΘΡΟΥ | E5: ΜΟΝΑΔΑ ΜΕΤΡΗΣΗΣ | F5: ΤΙΜΗ ΜΟΝΑΔΑΣ | G5: ΠΟΣΟΤΗΤΑ | H5: ΠΟΣΟ
B6: 50040843 | C6: 1956.i | D6: ΑΥΤΟΨΙΑ ΣΕ ΚΤΙΡΙΟ (SITE SURVEY) ΣΕ ΜΕΣΑΙΑ ΚΑΙ ΜΕΓΑΛΑ ΚΤΗΡΙΑ ΚΤΗΡΙΑ | E6: TEM | F6: 80 | G6: 1 | H6: =F6*G6 -> 80 | K6: 1000.1.I.α. Μ/Τ ΠΛ ΣΤ 8Χ30cm ΕΠΑΝ ΑΣΦΑΛΤΟΣήΣΚΥΡ FTTH
B7: 50040844 | C7: 1956.ii | D7: ΑΥΤΟΨΙΑ ΣΕ ΚΤΙΡΙΟ (SITE SURVEY) ΣΕ ΜΙΚΡΑ ΚΤΗΡΙΑ (έως 4 διεπαφές και κατανεμημένες σε έως 2 επίπεδα) | E7: TEM | F7: 50 | H7: =F7*G7 -> 0 | K7: 1000.1.I.β. Μ/Τ ΠΛ ΣΤ 8Χ45,10Χ45-50cm ΕΠΑΝ ΑΣΦΑ FTTH
B8: 50024274 | C8: 1963.i. | D8: ΕΠΕΚΤ ΣΩΛ ΔΙΑΝ FTTH-ΕΣΚΑΛ ΥΦ ΥΠ ΤΦΡ <5m | E8: TEM | F8: 150 | H8: =F8*G8 -> 0
B9: 50024275 | C9: 1963.ii. | D9: ΕΠΕΚΤ ΣΩΛ ΔΙΑΝ FTTH-ΕΣΚΑΛ ΥΦ ΥΠ ΤΦΡ <15m | E9: TEM | F9: 250 | H9: =F9*G9 -> 0
B10: 50040888 | C10: 1965.i. | D10: ΕΠΕΚ ΣΩΛ ΔΙΑΝ FTTH-ΠΕΛΑΤ ΝΕΑ ΥΠ ΔΙΑΝ <5m | E10: TEM | F10: 150 | H10: =F10*G10 -> 0 | K10: 1000.1.I.γ. Μ/Τ ΠΛ ΣΤ 16Χ45-16Χ50cm ΕΠΑΝ ΑΣΦΑΛΤ FTTH
B11: 50040889 | C11: 1965.ii. | D11: ΕΠΕΚ ΣΩΛ ΔΙΑΝ FTTH-ΠΕΛΑΤ ΝΕΑ ΥΠ ΔΙΑΝ<15m | E11: TEM | F11: 250 | H11: =F11*G11 -> 0 | K11: 1000.1.I.δ. Μ/Τ ΠΛ ΣΤ 16Χ55-16Χ60cm ΕΠΑΝ ΑΣΦΑΛΤ FTTH
B12: 50040890 | C12: 1965.iii. | D12: ΕΠΕΚ ΣΩΛ ΔΙΑΝ FTTH-ΠΕΛΑΤ ΝΕΑ ΥΠ ΔΙΑΝ<30m | E12: TEM | F12: 350 | H12: =F12*G12 -> 0 | K12: 1000.1.I.ε. Μ/Τ ΧΩΡ ΠΛ ΣΤ 5Χ30-6Χ30cm ΕΠΑΝ ΑΣΦΑ FTTH
B13: 50040891 | C13: 1965.iv. | D13: ΕΠΕΚ ΣΩΛ ΔΙΑΝ FTTH-ΠΕΛΑΤ ΝΕΑ ΥΠ ΔΙΑΝ<60m | E13: TEM | F13: 450 | H13: =F13*G13 -> 0 | K13: 1000.1.I.στ. Μ/Τ ΧΩΡ ΠΛ ΣΤ 5Χ45-6Χ45cm ΕΠΑΝ ΑΣΦΑ FTTH
B14: 50040892 | C14: 1965.V. | D14: ΕΠ ΤΟΠ 2 ΣΩΛ ΕΠΕΚΤ ΚΛ ΔΙΑΝ FTTH ΕΩΣ 5Μ | E14: TEM | F14: 160 | H14: =F14*G14 -> 0
B15: 50040893 | C15: 1965.VI. | D15: ΕΠ ΤΟΠ 2 ΣΩΛ ΕΠΕΚΤ ΚΛ ΔΙΑΝ FTTH ΕΩΣ 15Μ | E15: TEM | F15: 270 | H15: =F15*G15 -> 0
B16: 50040894 | C16: 1965.VII. | D16: ΕΠ ΤΟΠ 2 ΣΩΛ ΕΠΕΚΤ ΚΛ ΔΙΑΝ FTTH ΕΩΣ 30Μ | E16: TEM | F16: 380 | H16: =F16*G16 -> 0
B17: 50040895 | C17: 1965.VIII. | D17: ΕΠ ΤΟΠ 2 ΣΩΛ ΕΠΕΚΤ ΚΛ ΔΙΑΝ FTTH ΕΩΣ 60Μ | E17: TEM | F17: 490 | G17: 1 | H17: =F17*G17 -> 490
B18: 50040879 | C18: 1970.i | D18: ΤΟΠΟΘ BEP ΜΕ ΚΑΤΑΣ ΥΠΟΔ ΟΔΕΥΣΗΣ ΚΟΙ <10m | E18: TEM | F18: 50 | G18: 1 | H18: =F18*G18 -> 50 | K18: 1000.2.I.α. Μ/Τ ΠΛ ΣΤ 8Χ30cm ΧΩΡΙΣ ΕΠΑΝ ή ΑΔΙΑΜ FTTH
B19: 50040880 | C19: 1970.ii | D19: ΤΟΠΟΘ BEP ΜΕ ΚΑΤΑΣ ΥΠΟΔ ΟΔΕΥΣΗΣ ΚΟΙ <25m | E19: TEM | F19: 100 | H19: =F19*G19 -> 0 | K19: 1000.2.I.β. Μ/Τ ΠΛ ΣΤ 8Χ45,10Χ45-50cm ΧΩΡ ΕΠΑΝ FTTH
B20: 50040881 | C20: 1970.iii | D20: ΤΟΠΟΘ BEP ΜΕ ΚΑΤΑΣ ΥΠΟΔ ΟΔΕΥΣΗΣ ΚΟΙ <40m | E20: TEM | F20: 175 | H20: =F20*G20 -> 0 | K20: 1000.2.I.γ. Μ/Τ ΠΛ ΣΤ 16Χ45-16Χ50cm ΧΩΡΙΣ ΕΠΑΝ FTTH
B21: 50040882 | C21: 1970.iv | D21: ΤΟΠΟΘ ΚΚΚ ΚΑΙ ΔΙΑΣΥΝΔΕΣΗ ΜΕ BEP ΣΕ ΜΙΚΡΑ ΚΤΗΡΙΑ | E21: TEM | F21: 30 | H21: =F21*G21 -> 0 | K21: 1000.2.I.δ. Μ/Τ ΠΛ ΣΤ 16Χ55-16Χ60cm ΧΩΡΙΣ ΕΠΑΝ FTTH
B22: 50040883 | C22: 1970.v | D22: ΤΟΠΟΘ ΚΚΚ ΚΑΙ ΔΙΑΣΥΝΔΕΣΗ ΜΕ BEP ΣΕ ΜΕΣΑΙΑ ΚΑΙ ΜΕΓΑΛΑ ΚΤΗΡΙΑ ΚΤΗΡΙΑ | E22: TEM | F22: 50 | G22: 1 | H22: =F22*G22 -> 50 | K22: 1000.2.I.ε. Μ/Τ ΧΩΡ ΠΛ ΣΤ 5Χ30-6Χ30cm ΧΩΡ ΕΠΑΝ FTTH
B23: 50024283 | C23: 1971.I. | D23: ΑΝΤΚ/ΣΗ BEP ή FLOOR BOX FTTH <12 ΥΦ ΣΥΝΔ | E23: EA | F23: 45 | H23: =F23*G23 -> 0 | K23: 1000.2.I.στ. Μ/Τ ΧΩΡ ΠΛ ΣΤ 5Χ45-6Χ45cm ΧΩΡ ΕΠΑΝ FTTH
B24: 50024284 | C24: 1971.II. | D24: ΑΝΤΚ/ΣΗ BEP ή FLOOR BOX FTTH <32 ΥΦ ΣΥΝΔ | E24: EA | F24: 65 | H24: =F24*G24 -> 0 | K24: 1000.3.I.α. Μ/Τ ΠΛ ΣΤ 8Χ30cm ΕΠΑΝ ΛΟΙΠ ΔΙΑΜ ΠΕΡ FTTH
B25: 50024285 | C25: 1973.1 | D25: ΕΡΓ ΥΨΟ ΕΝΑΕΡΙΤΗ ΚΑΤΑΚ,ΟΡΙΖ ΥΠ ΚΑΛ FTTH | E25: EA | F25: 190 | H25: =F25*G25 -> 0 | K25: 1000.3.I.β. Μ/Τ ΠΛ ΣΤ 8Χ45,10Χ45-50cm ΕΠΑΝ ΛΟΙΠ FTTH
B26: 50024286 | C26: 1973.2 | D26: ΕΡΓ ΥΨΟ ΚΑΛΑΘΟΦΟΡ ΚΑΤΑΚ,ΟΡΙΖ ΥΠ ΚΑΛ FTTH | E26: EA | F26: 280 | H26: =F26*G26 -> 0 | K26: 1000.3.I.γ. Μ/Τ ΠΛ ΣΤ 16Χ45-16Χ50cm ΕΠΑΝ ΛΟΙΠ FTTH
B27: 50024287 | C27: 1973.3 | D27: ΕΡΓ ΥΨΟ ΙΚΡΙΩΜΑΤΩ ΚΑΤΑΚ,ΟΡΙΖ ΥΠ ΚΑΛ FTTH | E27: EA | F27: 380 | H27: =F27*G27 -> 0 | K27: 1000.3.I.δ. Μ/Τ ΠΛ ΣΤ 16Χ55-16Χ60cm ΕΠΑΝ ΛΟΙΠ FTTH
B28: 50024288 | C28: 1977.I | D28: ΕΓΚ/ΣΗ SPLITTER ΟΠΤΙΚΟΥ ΣΗΜΑΤΟΣ FTTH | E28: EA | F28: 20 | H28: =F28*G28 -> 0 | K28: 1000.3.I.ε. Μ/Τ ΧΩΡ ΠΛ ΣΤ 5Χ30-6Χ30cmΕΠΑΝ ΛΟΙΠ FTTH
B29: 50024289 | C29: 1977.II | D29: ΤΡΟΠΟΠΟΙΗΣΗ ΔΙΑΣΥΝΔΕΣΕΩΝ | E29: EA | F29: 10 | H29: =F29*G29 -> 0 | K29: 1000.3.I.στ. Μ/Τ ΧΩΡ ΠΛ ΣΤ 5Χ45-6Χ45cm ΕΠΑΝ ΛΟΙΠ FTTH
B30: 50039380 | C30: 1977.IΙΙ | D30: ΕΓΚ/ΣΗ SPLITTER ΣΕ BEP/BCP ΜΕΤΑ ΤΗΝ ΟΛΟΚΛ ΤΗΣ ΑΡΧΙΚΗΣ | E30: EA | F30: 40 | H30: =F30*G30 -> 0
B31: 50039390 | C31: 1977.IV | D31: ΟΜΑΔΟΠΟΙΗΜ ΕΓΚ/ΣΗ SPLITTER ΣΕ BEP/BCP ΜΕΤΑ ΤΗΝ ΟΛΟΚΛ ΤΗΣ ΑΡΧΙΚΗΣ | E31: EA | F31: 30 | H31: =F31*G31 -> 0
B32: 50024290 | C32: 1980.I. | D32: ΤΟΠ ΚΟΙ FTTH ΚΑΜΠ-ΤΕΡΜ ΔΙΑΤΑΞ ΕΛΕΥΘ ΥΠΟΔ | E32: TEM | F32: 180 | G32: 1 | H32: =F32*G32 -> 180 | K32: 1001 ΕΚΣΚΑΦΗ ΣΚΑΜΜΑΤΩΝ
B33: 50024291 | C33: 1980.II. | D33: ΤΟΠ ΚΟΙ FTTH ΚΑΜΠ-ΤΕΡΜ ΔΙΑΤΑΞ ΒΛΑΒΗ ΚΟΙ | E33: TEM | F33: 200 | H33: =F33*G33 -> 0 | K33: 1011 ΑΠΟΞΗΛΩΣΗ ΔΙΑΜΟΡΦΩΜΕΝΗΣ ΕΠΙΦΑΝΕΙΑΣ Μ/Τ
B34: 50024292 | C34: 1985.1 | D34: ΚΑΤ ΚΑΤΑΚΟΡ ΚΟΙ ΑΝΑ ΟΡΟΦ ΜΙΚΡΟΥΛ ΕΡΓΟΛ | E34: EA | F34: 55 | H34: =F34*G34 -> 0 | K34: 1015 ΑΠΟΚΑΛΥΨΗ ΚΑΠΑΚΙΟΥ ΦΡΕΑΤΙΟΥ
B35: 50024293 | C35: 1985.2 | D35: ΚΑΤ ΚΑΤΑΚΟΡ ΚΟΙ ΑΝΑ ΟΡΟΦ ΜΙΚΡΟ&ΥΛΙ ΕΡΓΟΛ | E35: EA | F35: 65 | G35: 4 | H35: =F35*G35 -> 260 | K35: 1020 ΕΚΣΚ ΛΑΚΚΟΥ ΓΙΑ ΕΝΤΟΠΙΣΜΟ ΚΑΛΩΔΙΑΚ ΒΛΑΒΗ
B36: 50024294 | C36: 1985.3 | D36: ΚΑΤ ΚΑΤΑΚΟΡ ΦΡ ΑΝΕΛΚ ΥΛΙΚ ΟΤΕ <5ΟΡΟΦ | E36: EA | F36: 230 | H36: =F36*G36 -> 0 | K36: 1021 ΕΚΣΚ ΛΑΚΚΟΥ ΜΟΥΦΑΣ ΣΥΜΜΕΤΡΙΚΩΝ ΚΑΛΩΔΙΩΝ
B37: 50024295 | C37: 1985.4 | D37: ΚΑΤ ΚΑΤΑΚΟΡ ΦΡ ΑΝΕΛΚ >5ΟΡΟΦ ΑΝΑ ΟΡΟΦ | E37: EA | F37: 40 | H37: =F37*G37 -> 0 | K37: 1024 ΕΚΣΚ ΛΑΚΚΟΥ ΜΟΥΦΑΣ ΚΑΛΩΔΙΩΝ ΟΠΤΙΚΩΝ ΙΝΩΝ
B38: 50040884 | C38: 1986.Ι | D38: ΤΟΠ ΚΟΙ FTTH ΚΑΤΑΚΟΡΥΦΗ ΥΠ,ΤΕΡΜΑΤ & ΔΙΑΣ ΕΩΣ 3 ΟΡ | E38: TEM | F38: 65 | H38: =F38*G38 -> 0 | K38: 1025 ΕΚΣΚ ΛΑΚΚΟΥ ΓΙΑ ΑΡΣΗ ΚΑΛΩΔΙΑΚΗΣ ΒΛΑΒΗΣ
B39: 50040885 | C39: 1986.ΙΙ | D39: ΤΟΠ ΚΟΙ FTTH ΚΑΤΑΚΟΡΥΦΗ ΥΠ,ΤΕΡΜΑΤ & ΔΙΑΣ ΕΠΙΠΛΕΟΝ ΤΩΝ 3 ΟΡ | E39: TEM | F39: 35 | H39: =F39*G39 -> 0
B40: 50040886 | C40: 1986.III. | D40: ΤΟΠ ΚΟΙ ΚΑΛ ΑΝΑΓ ΚΥΑ ΕΥΘ ΠΡ 3 ΠΡΩΤ ΟΡΟΦ | E40: TEM | F40: 82 | G40: 3 | H40: =F40*G40 -> 246
...

Sheet ΥΛΙΚΑ
A1: ΠΙΝΑΚΑΣ ΥΛΙΚΩΝ FTTH Β & Γ ΦΑΣΗ
A2: ΕΡΓΟΛΑΒΙΑ: | B2: ΑΝΑΠΤΥΞΗ ΥΠΟΔΟΜΩΝ ΠΡΟΣΒΑΣΗΣ ΔΙΚΤΥΟΥ ΟΠΤΙΚΩΝ ΙΝΩΝ (FTTH Β ΦΑΣΗ) & ΔΙΑΣΥΝΔΕΣΗΣ ΤΟΝ ΤΕΛΙΚΟ ΧΡΗΣΤΗ (FTTH Γ ΦΑΣΗ) ΣΕ ΠΕΡΙΟΧΕΣ ΤΗΣ ΕΛΛΗΝΙΚΗΣ ΕΠΙΚΡΑΤΕΙΑΣ | D2: ΕΡΓΟΛΑΒΟΣ: | E2: ΕΡΓΑΤΗΚΑΤ
A3: ΥΠΟΕΡΓΟ: | B3: ='ΦΥΛΛΟ ΑΠΟΛΟΓΙΣΜΟΥ'!C3 | C3: ΑΙΤΗΜΑ: | D3: ='ΦΥΛΛΟ ΑΠΟΛΟΓΙΣΜΟΥ'!F3 -> 979273
A4: ΔΙΕΥΘΥΝΣΗ: | B4: ='ΦΥΛΛΟ ΑΠΟΛΟΓΙΣΜΟΥ'!C4 -> ΛΕΩΦΟΡΟΣ ΓΕΩΡΓΙΟΥ ΑΒΕΡΩΦ 101Α
B5: ΠΕΡΙΓΡΑΦΗ ΥΛΙΚΩΝ | C5: ΜΟΝ. ΜΕΤΡ. | D5: ΚΑΥ | E5: ΠΟΣΟΤΗΤΑ
B6: Microduct 7-4mm DB | C6: ΜΕΤΡΟ | D6: 14026586 | E6: 34
B7: Microduct 7/4 mm indoor LSZH | C7: ΜΕΤΡΟ | D7: 14027164
B8: Microduct Μde -D- 8/10mm | C8: ΜΕΤΡΟ | D8: 14034374 | E8: 34
B9: Multiduct flat 6x7/4 mm indoor LSZH | C9: ΜΕΤΡΟ | D9: 14027165
B10: ΤΑΠΕΣ ΣΩΛΗΝΙΣΚΩΝ ΠΟΛΥΣΩΛΗΝΙΟΥ D=10/12mm | C10: ΤΕΜΑΧΙΟ | D10: 14024326
B11: ΣΥΝΔΕΣΜΟΙ ΣΩΛΗΝΙΣΚΩΝ ΠΟΛΥΣΩΛΗΝ D=10/12mm | C11: ΤΕΜΑΧΙΟ | D11: 14024327
B12: Microduct Μde -D- 10/12mm | C12: ΜΕΤΡΟ | D12: 14020192 | E12: 1
B13: Straight connector 7-4mm DB | C13: ΤΕΜΑΧΙΟ | D13: 14026588 | E13: 1
B14: Endcaps 7-4mm | C14: ΤΕΜΑΧΙΟ | D14: 14026613 | E14: 1
B15: END CAPS 8/10mm | C15: ΤΕΜΑΧΙΟ | D15: 14019470 | E15: 1
B16: Individual divisible sealing 7/2,5mm | C16: ΤΕΜΑΧΙΟ | D16: 14026591 | E16: 1
B17: Patchcord SC/APC-SC/APC 2M G.657A1/A2 | C17: ΤΕΜΑΧΙΟ | D17: 14033652 | E17: 19
B18: Patchcord SC/APC-SC/APC 3M G.657A1/A2 | C18: ΤΕΜΑΧΙΟ | D18: 14034101
B19: Patchcord SC/APC-SC/APC 4M G.657A1/A2 | C19: ΤΕΜΑΧΙΟ | D19: 14033661
B20: Ενδεικτικό Πλέγμα Σήμανσης 20cm Ανιχευσ. | C20: ΜΕΤΡΟ | D20: 14023051 | E20: 14
B21: Small BMO | C21: ΤΕΜΑΧΙΟ | D21: 14034167
B22: Medium BMO | C22: ΤΕΜΑΧΙΟ | D22: 14034168 | E22: 1
B23: Large BMO | C23: ΤΕΜΑΧΙΟ | D23: 14034169
B24: Small BEP | C24: ΤΕΜΑΧΙΟ | D24: 14029065
B25: Small BEP with 1 splitter preinstalled | C25: ΤΕΜΑΧΙΟ | D25: 14028868
B26: Medium BEP | C26: ΤΕΜΑΧΙΟ | D26: 14029066
B27: Medium BEP with 1 splitter preinstalled | C27: ΤΕΜΑΧΙΟ | D27: 14028869
B28: Large BEP with 1 splitter preinstalled | C28: ΤΕΜΑΧΙΟ | D28: 14034514 | E28: 1
B29: X-Large BEP with 1 splitter preinstalled | C29: ΤΕΜΑΧΙΟ | D29: 14028871
B30: BEP PLC SPLITTERS 1:2 | C30: ΤΕΜΑΧΙΟ | D30: 14029061 | E30: 1
B31: BEP PLC SPLITTERS 1:8 | C31: ΤΕΜΑΧΙΟ | D31: 14029062
B32: Floor-box with 2 adapters | C32: ΤΕΜΑΧΙΟ | D32: 14028873
B33: Floor-box with 4 adapters | C33: ΤΕΜΑΧΙΟ | D33: 14034172 | E33: 1
B34: Floor-box with 6 adapters | C34: ΤΕΜΑΧΙΟ | D34: 14028872
B35: Floor-box with 12 adapters | C35: ΤΕΜΑΧΙΟ | D35: 14034173 | E35: 4
B36: OTO Fiber outlets SC/APC | C36: ΤΕΜΑΧΙΟ | D36: 14028924
B37: Prefibered OTO 20m O2a-5941 | C37: ΤΕΜΑΧΙΟ | D37: 14029175
B38: Prefibered OTO 30m O2b-5941 | C38: ΤΕΜΑΧΙΟ | D38: 14029176
B39: 4 FO outdoor induct micro cable G657A | C39: ΜΕΤΡΟ | D39: 14027440 | E39: 407
B40: 12 FO outdoor induct micro cable G657A | C40: ΜΕΤΡΟ | D40: 14027441
...

Sheet ΤΙΜΟΚΑΤΑΛΟΓΟΣ
A1: Activity Number | B1: ΑΡΘΡΟ | C1: ΠΕΡΙΓΡΑΦΗ ΕΡΓΑΣΙΩΝ | D1: ΜΟΝΑΔΑ ΜΕΤΡΗΣΗΣ | E1: ΤΙΜΗ ΟΤΕ
A2: 50040873 | B2: 1955.I. | C2: ΚΑΤ ΝΕΟ ΠΕΛ ΚΑΤΑΚ ΥΠ ΟΔ FTTH KOI | D2: TEM | E2: 35
A3: 50040874 | B3: 1955.II. | C3: ΚΑΤ ΣΥΝΔ ΝΕΟ ΠΕΛ ΚΑΤΑΚ ΥΠ ΟΔ FTTH KOI | D3: TEM | E3: 65
A4: 50040875 | B4: 1955.III. | C4: ΚΑΤ ΝΕΟ ΠΕΛ ΜΕΤΑ ΟΛ ΚΑΤΑΚ ΥΠ ΟΔ FTTH KOI | D4: TEM | E4: 75
A5: 50040876 | B5: 1955.IV. | C5: ΚΑΤ ΣΥΝΔ ΝΕΟ ΠΕΛ ΜΕΤΑ ΚΑΤ ΥΠ ΟΔ FTTH KOI | D5: TEM | E5: 105
A6: 50040877 | B6: 1955.V. | C6: ΑΠΟΚ ΣΥΝΔ ΠΕΛ ΤΟΠ ΤΕΡΜ ΟΡ ΚΑΛ ΟΡ | D6: TEM | E6: 50
A7: 50040878 | B7: 1955.VI. | C7: ΕΠΙΠΡΟΣΘΕΤΗ ΑΠΟΖΗΜΙΩΣΗ ΓΙΑ ΌΛΑ ΤΜΗΜΑΤΑ | D7: TEM | E7: 45
A8: 50040843 | B8: 1956.I. | C8: ΑΥΤΟΨ ΜΕΣ ΜΕΓ ΚΤ ΑΝAM FTTH ΚΛ ΔΙΑΝ BCP | D8: TEM | E8: 80
A9: 50040844 | B9: 1956.II. | C9: ΑΥΤΟΨ ΜΙΚΡΟ ΚΤ ΑΝAM FTTH ΚΛ ΔΙΑΝ BCP | D9: TEM | E9: 50
A10: 50040845 | B10: 1957.I. | C10: ΥΛ ΥΠ FTTH ΚΤ ΕΩΣ2 ΕΠ SMART READ VOUCHER | D10: TEM | E10: 50
A11: 50040846 | B11: 1957.II. | C11: ΥΛ ΥΠ FTTH ΚΤ 3 ΕΠ SMART READ VOUCHER | D11: TEM | E11: 270
A12: 50040847 | B12: 1957.III. | C12: ΥΛ ΥΠ FTTH ΚΤ 4ΑΝΩ ΕΠ SMART READ VOUCHER | D12: TEM | E12: 300
A13: 50040848 | B13: 1957.IV. | C13: ΥΛ ΥΠ FTTH ΚΤ ΕΩΣ 2 ΕΠ SM.R.V.KYA | D13: TEM | E13: 130
... A821: 50023833 | B821: Ν4611.4 | C821: ΑΝΟΙΓΜΑ ΚΑΛΩΔ/ΣΥΝΔ ΣΕ ΤΑΦΡΟ 1200-2400'' | D821: TEM | E821: 117.39785

Sheet ΛΟΓΑΡΙΑΣΜΟΣ
A1: ΑΡΘΡΟ | B1: Activity Number | C1: ΠΟΣΟΤΗΤΑ | D1: ΤΙΜΗ ΟΤΕ | E1: ΠΟΣΟ
A2: =IF('ΦΥΛΛΟ ΑΠΟΛΟΓΙΣΜΟΥ'!G6>0,'ΦΥΛΛΟ ΑΠΟΛΟΓΙΣΜΟΥ'!C6," ") -> 1956.i | B2: =IF('ΦΥΛΛΟ ΑΠΟΛΟΓΙΣΜΟΥ'!G6>0,'ΦΥΛΛΟ ΑΠΟΛΟΓΙΣΜΟΥ'!B6," ") -> 50040843 | C2: =IF('ΦΥΛΛΟ ΑΠΟΛΟΓΙΣΜΟΥ'!G6>0,'ΦΥΛΛΟ ΑΠΟΛΟΓΙΣΜΟΥ'!G6,0) -> 1 | D2: ='ΦΥΛΛΟ ΑΠΟΛΟΓΙΣΜΟΥ'!F6 -> 80 | E2: =C2*D2 -> 80
A3: =IF('ΦΥΛΛΟ ΑΠΟΛΟΓΙΣΜΟΥ'!G7>0,'ΦΥΛΛΟ ΑΠΟΛΟΓΙΣΜΟΥ'!C7," ") | B3: =IF('ΦΥΛΛΟ ΑΠΟΛΟΓΙΣΜΟΥ'!G7>0,'ΦΥΛΛΟ ΑΠΟΛΟΓΙΣΜΟΥ'!B7," ") | C3: =IF('ΦΥΛΛΟ ΑΠΟΛΟΓΙΣΜΟΥ'!G7>0,'ΦΥΛΛΟ ΑΠΟΛΟΓΙΣΜΟΥ'!G7,0) -> 0 | D3: ='ΦΥΛΛΟ ΑΠΟΛΟΓΙΣΜΟΥ'!F7 -> 50 | E3: =C3*D3 -> 0
A4: =IF('ΦΥΛΛΟ ΑΠΟΛΟΓΙΣΜΟΥ'!G8>0,'ΦΥΛΛΟ ΑΠΟΛΟΓΙΣΜΟΥ'!C8," ") | B4: =IF('ΦΥΛΛΟ ΑΠΟΛΟΓΙΣΜΟΥ'!G8>0,'ΦΥΛΛΟ ΑΠΟΛΟΓΙΣΜΟΥ'!B8," ") | C4: =IF('ΦΥΛΛΟ ΑΠΟΛΟΓΙΣΜΟΥ'!G8>0,'ΦΥΛΛΟ ΑΠΟΛΟΓΙΣΜΟΥ'!G8,0) -> 0 | D4: ='ΦΥΛΛΟ ΑΠΟΛΟΓΙΣΜΟΥ'!F8 -> 150 | E4: =C4*D4 -> 0
A5: =IF('ΦΥΛΛΟ ΑΠΟΛΟΓΙΣΜΟΥ'!G9>0,'ΦΥΛΛΟ ΑΠΟΛΟΓΙΣΜΟΥ'!C9," ") | B5: =IF('ΦΥΛΛΟ ΑΠΟΛΟΓΙΣΜΟΥ'!G9>0,'ΦΥΛΛΟ ΑΠΟΛΟΓΙΣΜΟΥ'!B9," ") | C5: =IF('ΦΥΛΛΟ ΑΠΟΛΟΓΙΣΜΟΥ'!G9>0,'ΦΥΛΛΟ ΑΠΟΛΟΓΙΣΜΟΥ'!G9,0) -> 0 | D5: ='ΦΥΛΛΟ ΑΠΟΛΟΓΙΣΜΟΥ'!F9 -> 250 | E5: =C5*D5 -> 0
A6: =IF('ΦΥΛΛΟ ΑΠΟΛΟΓΙΣΜΟΥ'!G10>0,'ΦΥΛΛΟ ΑΠΟΛΟΓΙΣΜΟΥ'!C10," ") | B6: =IF('ΦΥΛΛΟ ΑΠΟΛΟΓΙΣΜΟΥ'!G10>0,'ΦΥΛΛΟ ΑΠΟΛΟΓΙΣΜΟΥ'!B10," ") | C6: =IF('ΦΥΛΛΟ ΑΠΟΛΟΓΙΣΜΟΥ'!G10>0,'ΦΥΛΛΟ ΑΠΟΛΟΓΙΣΜΟΥ'!G10,0) -> 0 | D6: ='ΦΥΛΛΟ ΑΠΟΛΟΓΙΣΜΟΥ'!F10 -> 150 | E6: =C6*D6 -> 0
A7: =IF('ΦΥΛΛΟ ΑΠΟΛΟΓΙΣΜΟΥ'!G11>0,'ΦΥΛΛΟ ΑΠΟΛΟΓΙΣΜΟΥ'!C11," ") | B7: =IF('ΦΥΛΛΟ ΑΠΟΛΟΓΙΣΜΟΥ'!G11>0,'ΦΥΛΛΟ ΑΠΟΛΟΓΙΣΜΟΥ'!B11," ") | C7: =IF('ΦΥΛΛΟ ΑΠΟΛΟΓΙΣΜΟΥ'!G11>0,'ΦΥΛΛΟ ΑΠΟΛΟΓΙΣΜΟΥ'!G11,0) -> 0 | D7: ='ΦΥΛΛΟ ΑΠΟΛΟΓΙΣΜΟΥ'!F11 -> 250 | E7: =C7*D7 -> 0
A8: =IF('ΦΥΛΛΟ ΑΠΟΛΟΓΙΣΜΟΥ'!G12>0,'ΦΥΛΛΟ ΑΠΟΛΟΓΙΣΜΟΥ'!C12," ") | B8: =IF('ΦΥΛΛΟ ΑΠΟΛΟΓΙΣΜΟΥ'!G12>0,'ΦΥΛΛΟ ΑΠΟΛΟΓΙΣΜΟΥ'!B12," ") | C8: =IF('ΦΥΛΛΟ ΑΠΟΛΟΓΙΣΜΟΥ'!G12>0,'ΦΥΛΛΟ ΑΠΟΛΟΓΙΣΜΟΥ'!G12,0) -> 0 | D8: ='ΦΥΛΛΟ ΑΠΟΛΟΓΙΣΜΟΥ'!F12 -> 350 | E8: =C8*D8 -> 0
A9: =IF('ΦΥΛΛΟ ΑΠΟΛΟΓΙΣΜΟΥ'!G13>0,'ΦΥΛΛΟ ΑΠΟΛΟΓΙΣΜΟΥ'!C13," ") | B9: =IF('ΦΥΛΛΟ ΑΠΟΛΟΓΙΣΜΟΥ'!G13>0,'ΦΥΛΛΟ ΑΠΟΛΟΓΙΣΜΟΥ'!B13," ") | C9: =IF('ΦΥΛΛΟ ΑΠΟΛΟΓΙΣΜΟΥ'!G13>0,'ΦΥΛΛΟ ΑΠΟΛΟΓΙΣΜΟΥ'!G13,0) -> 0 | D9: ='ΦΥΛΛΟ ΑΠΟΛΟΓΙΣΜΟΥ'!F13 -> 450 | E9: =C9*D9 -> 0
A10: =IF('ΦΥΛΛΟ ΑΠΟΛΟΓΙΣΜΟΥ'!G14>0,'ΦΥΛΛΟ ΑΠΟΛΟΓΙΣΜΟΥ'!C14," ") | B10: =IF('ΦΥΛΛΟ ΑΠΟΛΟΓΙΣΜΟΥ'!G14>0,'ΦΥΛΛΟ ΑΠΟΛΟΓΙΣΜΟΥ'!B14," ") | C10: =IF('ΦΥΛΛΟ ΑΠΟΛΟΓΙΣΜΟΥ'!G14>0,'ΦΥΛΛΟ ΑΠΟΛΟΓΙΣΜΟΥ'!G14,0) -> 0 | D10: ='ΦΥΛΛΟ ΑΠΟΛΟΓΙΣΜΟΥ'!F14 -> 160 | E10: =C10*D10 -> 0
A11: =IF('ΦΥΛΛΟ ΑΠΟΛΟΓΙΣΜΟΥ'!G15>0,'ΦΥΛΛΟ ΑΠΟΛΟΓΙΣΜΟΥ'!C15," ") | B11: =IF('ΦΥΛΛΟ ΑΠΟΛΟΓΙΣΜΟΥ'!G15>0,'ΦΥΛΛΟ ΑΠΟΛΟΓΙΣΜΟΥ'!B15," ") | C11: =IF('ΦΥΛΛΟ ΑΠΟΛΟΓΙΣΜΟΥ'!G15>0,'ΦΥΛΛΟ ΑΠΟΛΟΓΙΣΜΟΥ'!G15,0) -> 0 | D11: ='ΦΥΛΛΟ ΑΠΟΛΟΓΙΣΜΟΥ'!F15 -> 270 | E11: =C11*D11 -> 0
A12: =IF('ΦΥΛΛΟ ΑΠΟΛΟΓΙΣΜΟΥ'!G16>0,'ΦΥΛΛΟ ΑΠΟΛΟΓΙΣΜΟΥ'!C16," ") | B12: =IF('ΦΥΛΛΟ ΑΠΟΛΟΓΙΣΜΟΥ'!G16>0,'ΦΥΛΛΟ ΑΠΟΛΟΓΙΣΜΟΥ'!B16," ") | C12: =IF('ΦΥΛΛΟ ΑΠΟΛΟΓΙΣΜΟΥ'!G16>0,'ΦΥΛΛΟ ΑΠΟΛΟΓΙΣΜΟΥ'!G16,0) -> 0 | D12: ='ΦΥΛΛΟ ΑΠΟΛΟΓΙΣΜΟΥ'!F16 -> 380 | E12: =C12*D12 -> 0
A13: =IF('ΦΥΛΛΟ ΑΠΟΛΟΓΙΣΜΟΥ'!G17>0,'ΦΥΛΛΟ ΑΠΟΛΟΓΙΣΜΟΥ'!C17," ") -> 1965.VIII. | B13: =IF('ΦΥΛΛΟ ΑΠΟΛΟΓΙΣΜΟΥ'!G17>0,'ΦΥΛΛΟ ΑΠΟΛΟΓΙΣΜΟΥ'!B17," ") -> 50040895 | C13: =IF('ΦΥΛΛΟ ΑΠΟΛΟΓΙΣΜΟΥ'!G17>0,'ΦΥΛΛΟ ΑΠΟΛΟΓΙΣΜΟΥ'!G17,0) -> 1 | D13: ='ΦΥΛΛΟ ΑΠΟΛΟΓΙΣΜΟΥ'!F17 -> 490 | E13: =C13*D13 -> 490
... A92: =IF('ΦΥΛΛΟ ΑΠΟΛΟΓΙΣΜΟΥ'!G96>0,'ΦΥΛΛΟ ΑΠΟΛΟΓΙΣΜΟΥ'!C96," ") | B92: =IF('ΦΥΛΛΟ ΑΠΟΛΟΓΙΣΜΟΥ'!G96>0,'ΦΥΛΛΟ ΑΠΟΛΟΓΙΣΜΟΥ'!B96," ") | C92: =IF('ΦΥΛΛΟ ΑΠΟΛΟΓΙΣΜΟΥ'!G96>0,'ΦΥΛΛΟ ΑΠΟΛΟΓΙΣΜΟΥ'!G96,0) -> 0 | D92: ='ΦΥΛΛΟ ΑΠΟΛΟΓΙΣΜΟΥ'!F96 -> 0.95 | E92: =C92*D92 -> 0
D93: ΣΥΝΟΛΟ ΕΡΓΑΣΙΩΝ: (ΤΙΜΗ ΟΤΕ) | E93: =SUM(E2:E92) -> 1488
A94: ΠΟΣΟΣΤΟ ΕΚΠΤΩΣΗΣ | B94: ='ΦΥΛΛΟ ΑΠΟΛΟΓΙΣΜΟΥ'!E97 | D94: ΣΥΝΟΛΟ ΕΡΓΑΣΙΩΝ: (ΤΙΜΗ ΕΡΓΑΤΗΚΑΤ) | E94: =E93*(1-B94) -> 1488
